<!-- description of the CamBot robot, a robotics project for the UVic-UCC master in robotics first term -->
<robot name = "mybot">

	<!-- BASE-FOOTPRINT -->
	<!-- base_footprint is a fictitious link(frame) that is on the ground right below base_link origin, navigation stack depends on this frame -->
	<link name = "base_footprint"/>

	<joint name = "base_footprint_joint" type = "fixed">
		<parent link = "base_footprint"/>
		<child link = "base_link"/>
		<origin xyz = "0 0 0" rpy = "0 0 0"/>
	</joint>

	<!-- BASE-LINK -->
    <!--Actual body/chassis of the robot-->
	<link name = "base_link">
		<visual>
			<origin xyz = "0 0 0.038" rpy = "0 0 -1.57"/>
			<geometry>
				<mesh filename = "package://mybot_description/meshes/mybot_base.stl"/>
			</geometry>
			<material name = "mybot/red">
				<color rgba = "1.0 0.0 0.0 1.0"/>
			</material>
		</visual>
	</link>

	<joint name = "base_to_right_wheel" type = "continuous">
		<parent link = "base_link"/>
		<child link = "right_wheel_link"/>
		<origin xyz = "0.023 -0.050 0.041" rpy = "1.57 0 0"/>
		<axis xyz = "0 0 1"/>
	</joint>

	<joint name = "base_to_left_wheel" type = "continuous">
		<parent link = "base_link"/>
		<child link = "left_wheel_link"/>
		<origin xyz = "0.023 0.050 0.041" rpy = "-1.57 0 0"/>
		<axis xyz = "0 0 1"/>
	</joint>

	<joint name = "base_to_ultrasound" type = "fixed">
		<parent link = "base_link"/>
		<child link = "ultrasound_link"/>
		<origin xyz = "0.06 0 0.08" rpy = "0 0 0"/>
	</joint>
	<link name="ultrasound_link"/>

	<!-- WHEEL-LINKS -->
    <!--Actual wheels of the robot-->
	<link name = "left_wheel_link">
		<visual>
			<origin xyz = "0 0 0.005" rpy = "0 1.57 0" />
			<geometry>
				<mesh filename = "package://mybot_description/meshes/mybot_wheel.stl" />
			</geometry>
			<material name = "cambot/black">
				<color rgba = "0.0 0.0 0.0 1.0" />
			</material>
		</visual>
	</link>

	<link name = "right_wheel_link">
		<visual>
			<origin xyz = "0 0 0.005" rpy = "0 1.57 0" />
			<geometry>
				<mesh filename = "package://mybot_description/meshes/mybot_wheel.stl" />
			</geometry>
			<material name = "cambot/black">
				<color rgba = "0.0 0.0 0.0 1.0" />
			</material>
		</visual>
	</link>
</robot>